Workbook

Sheet Service_Input
A1: Region | B1: Service | C1: Language | D1: Status | E1: Lookup_Key
A2: USA | B2: ASR | C2: English | D2: Full Support (Cross-Region) | E2: =A2&"|"&B2&"|"&C2
A3: USA | B3: ASR | C3: Hindi | D3: Not Supported | E3: =A3&"|"&B3&"|"&C3
A4: USA | B4: ASR | C4: Spanish | D4: Full Support (Cross-Region) | E4: =A4&"|"&B4&"|"&C4
A5: USA | B5: ASR | C5: German | D5: Not Supported | E5: =A5&"|"&B5&"|"&C5
A6: USA | B6: ASR | C6: Arabic | D6: Limited Support (In-Region) | E6: =A6&"|"&B6&"|"&C6
A7: USA | B7: ASR | C7: French | D7: Full Support (In-Region) | E7: =A7&"|"&B7&"|"&C7
A8: USA | B8: ASR | C8: Italian | D8: Full Support (Cross-Region) | E8: =A8&"|"&B8&"|"&C8
A9: USA | B9: Redaction | C9: English | D9: Limited Support (Cross-Region) | E9: =A9&"|"&B9&"|"&C9
A10: USA | B10: Redaction | C10: Hindi | D10: Full Support (In-Region) | E10: =A10&"|"&B10&"|"&C10
A11: USA | B11: Redaction | C11: Spanish | D11: Limited Support (Cross-Region) | E11: =A11&"|"&B11&"|"&C11
A12: USA | B12: Redaction | C12: German | D12: Limited Support (Cross-Region) | E12: =A12&"|"&B12&"|"&C12
A13: USA | B13: Redaction | C13: Arabic | D13: Limited Support (In-Region) | E13: =A13&"|"&B13&"|"&C13
... A386: Saudi | B386: KaaS | C386: Italian | D386: Full Support (In-Region) | E386: =A386&"|"&B386&"|"&C386

Sheet Service_Dashboard
B2: SERVICE AVAILABILITY MATRIX
B4: Select Region: | C4: USA
A7: Language | B7: ASR | C7: Redaction | D7: Conversation Facts | E7: Gen AI Disposition | F7: ITN | G7: Intent (UniFit) | H7: Entity (NER/Spacy) | I7: Gen AI Summary | J7: Pro-active Service | K7: SSA-LLM | L7: KaaS
A8: English | B8: =INDEX(Service_Input!$D:$D, MATCH($C$4&"|"&B$7&"|"&$A8, Service_Input!$E:$E, 0)) | C8: =INDEX(Service_Input!$D:$D, MATCH($C$4&"|"&C$7&"|"&$A8, Service_Input!$E:$E, 0)) | D8: =INDEX(Service_Input!$D:$D, MATCH($C$4&"|"&D$7&"|"&$A8, Service_Input!$E:$E, 0)) | E8: =INDEX(Service_Input!$D:$D, MATCH($C$4&"|"&E$7&"|"&$A8, Service_Input!$E:$E, 0)) | F8: =INDEX(Service_Input!$D:$D, MATCH($C$4&"|"&F$7&"|"&$A8, Service_Input!$E:$E, 0)) | G8: =INDEX(Service_Input!$D:$D, MATCH($C$4&"|"&G$7&"|"&$A8, Service_Input!$E:$E, 0)) | H8: =INDEX(Service_Input!$D:$D, MATCH($C$4&"|"&H$7&"|"&$A8, Service_Input!$E:$E, 0)) | I8: =INDEX(Service_Input!$D:$D, MATCH($C$4&"|"&I$7&"|"&$A8, Service_Input!$E:$E, 0)) | ... L8: =INDEX(Service_Input!$D:$D, MATCH($C$4&"|"&L$7&"|"&$A8, Service_Input!$E:$E, 0))
A9: Hindi | B9: =INDEX(Service_Input!$D:$D, MATCH($C$4&"|"&B$7&"|"&$A9, Service_Input!$E:$E, 0)) | C9: =INDEX(Service_Input!$D:$D, MATCH($C$4&"|"&C$7&"|"&$A9, Service_Input!$E:$E, 0)) | D9: =INDEX(Service_Input!$D:$D, MATCH($C$4&"|"&D$7&"|"&$A9, Service_Input!$E:$E, 0)) | E9: =INDEX(Service_Input!$D:$D, MATCH($C$4&"|"&E$7&"|"&$A9, Service_Input!$E:$E, 0)) | F9: =INDEX(Service_Input!$D:$D, MATCH($C$4&"|"&F$7&"|"&$A9, Service_Input!$E:$E, 0)) | G9: =INDEX(Service_Input!$D:$D, MATCH($C$4&"|"&G$7&"|"&$A9, Service_Input!$E:$E, 0)) | H9: =INDEX(Service_Input!$D:$D, MATCH($C$4&"|"&H$7&"|"&$A9, Service_Input!$E:$E, 0)) | I9: =INDEX(Service_Input!$D:$D, MATCH($C$4&"|"&I$7&"|"&$A9, Service_Input!$E:$E, 0)) | ... L9: =INDEX(Service_Input!$D:$D, MATCH($C$4&"|"&L$7&"|"&$A9, Service_Input!$E:$E, 0))
A10: Spanish | B10: =INDEX(Service_Input!$D:$D, MATCH($C$4&"|"&B$7&"|"&$A10, Service_Input!$E:$E, 0)) | C10: =INDEX(Service_Input!$D:$D, MATCH($C$4&"|"&C$7&"|"&$A10, Service_Input!$E:$E, 0)) | D10: =INDEX(Service_Input!$D:$D, MATCH($C$4&"|"&D$7&"|"&$A10, Service_Input!$E:$E, 0)) | E10: =INDEX(Service_Input!$D:$D, MATCH($C$4&"|"&E$7&"|"&$A10, Service_Input!$E:$E, 0)) | F10: =INDEX(Service_Input!$D:$D, MATCH($C$4&"|"&F$7&"|"&$A10, Service_Input!$E:$E, 0)) | G10: =INDEX(Service_Input!$D:$D, MATCH($C$4&"|"&G$7&"|"&$A10, Service_Input!$E:$E, 0)) | H10: =INDEX(Service_Input!$D:$D, MATCH($C$4&"|"&H$7&"|"&$A10, Service_Input!$E:$E, 0)) | I10: =INDEX(Service_Input!$D:$D, MATCH($C$4&"|"&I$7&"|"&$A10, Service_Input!$E:$E, 0)) | ... L10: =INDEX(Service_Input!$D:$D, MATCH($C$4&"|"&L$7&"|"&$A10, Service_Input!$E:$E, 0))
A11: German | B11: =INDEX(Service_Input!$D:$D, MATCH($C$4&"|"&B$7&"|"&$A11, Service_Input!$E:$E, 0)) | C11: =INDEX(Service_Input!$D:$D, MATCH($C$4&"|"&C$7&"|"&$A11, Service_Input!$E:$E, 0)) | D11: =INDEX(Service_Input!$D:$D, MATCH($C$4&"|"&D$7&"|"&$A11, Service_Input!$E:$E, 0)) | E11: =INDEX(Service_Input!$D:$D, MATCH($C$4&"|"&E$7&"|"&$A11, Service_Input!$E:$E, 0)) | F11: =INDEX(Service_Input!$D:$D, MATCH($C$4&"|"&F$7&"|"&$A11, Service_Input!$E:$E, 0)) | G11: =INDEX(Service_Input!$D:$D, MATCH($C$4&"|"&G$7&"|"&$A11, Service_Input!$E:$E, 0)) | H11: =INDEX(Service_Input!$D:$D, MATCH($C$4&"|"&H$7&"|"&$A11, Service_Input!$E:$E, 0)) | I11: =INDEX(Service_Input!$D:$D, MATCH($C$4&"|"&I$7&"|"&$A11, Service_Input!$E:$E, 0)) | ... L11: =INDEX(Service_Input!$D:$D, MATCH($C$4&"|"&L$7&"|"&$A11, Service_Input!$E:$E, 0))
A12: Arabic | B12: =INDEX(Service_Input!$D:$D, MATCH($C$4&"|"&B$7&"|"&$A12, Service_Input!$E:$E, 0)) | C12: =INDEX(Service_Input!$D:$D, MATCH($C$4&"|"&C$7&"|"&$A12, Service_Input!$E:$E, 0)) | D12: =INDEX(Service_Input!$D:$D, MATCH($C$4&"|"&D$7&"|"&$A12, Service_Input!$E:$E, 0)) | E12: =INDEX(Service_Input!$D:$D, MATCH($C$4&"|"&E$7&"|"&$A12, Service_Input!$E:$E, 0)) | F12: =INDEX(Service_Input!$D:$D, MATCH($C$4&"|"&F$7&"|"&$A12, Service_Input!$E:$E, 0)) | G12: =INDEX(Service_Input!$D:$D, MATCH($C$4&"|"&G$7&"|"&$A12, Service_Input!$E:$E, 0)) | H12: =INDEX(Service_Input!$D:$D, MATCH($C$4&"|"&H$7&"|"&$A12, Service_Input!$E:$E, 0)) | I12: =INDEX(Service_Input!$D:$D, MATCH($C$4&"|"&I$7&"|"&$A12, Service_Input!$E:$E, 0)) | ... L12: =INDEX(Service_Input!$D:$D, MATCH($C$4&"|"&L$7&"|"&$A12, Service_Input!$E:$E, 0))
A13: French | B13: =INDEX(Service_Input!$D:$D, MATCH($C$4&"|"&B$7&"|"&$A13, Service_Input!$E:$E, 0)) | C13: =INDEX(Service_Input!$D:$D, MATCH($C$4&"|"&C$7&"|"&$A13, Service_Input!$E:$E, 0)) | D13: =INDEX(Service_Input!$D:$D, MATCH($C$4&"|"&D$7&"|"&$A13, Service_Input!$E:$E, 0)) | E13: =INDEX(Service_Input!$D:$D, MATCH($C$4&"|"&E$7&"|"&$A13, Service_Input!$E:$E, 0)) | F13: =INDEX(Service_Input!$D:$D, MATCH($C$4&"|"&F$7&"|"&$A13, Service_Input!$E:$E, 0)) | G13: =INDEX(Service_Input!$D:$D, MATCH($C$4&"|"&G$7&"|"&$A13, Service_Input!$E:$E, 0)) | H13: =INDEX(Service_Input!$D:$D, MATCH($C$4&"|"&H$7&"|"&$A13, Service_Input!$E:$E, 0)) | I13: =INDEX(Service_Input!$D:$D, MATCH($C$4&"|"&I$7&"|"&$A13, Service_Input!$E:$E, 0)) | ... L13: =INDEX(Service_Input!$D:$D, MATCH($C$4&"|"&L$7&"|"&$A13, Service_Input!$E:$E, 0))
A14: Italian | B14: =INDEX(Service_Input!$D:$D, MATCH($C$4&"|"&B$7&"|"&$A14, Service_Input!$E:$E, 0)) | C14: =INDEX(Service_Input!$D:$D, MATCH($C$4&"|"&C$7&"|"&$A14, Service_Input!$E:$E, 0)) | D14: =INDEX(Service_Input!$D:$D, MATCH($C$4&"|"&D$7&"|"&$A14, Service_Input!$E:$E, 0)) | E14: =INDEX(Service_Input!$D:$D, MATCH($C$4&"|"&E$7&"|"&$A14, Service_Input!$E:$E, 0)) | F14: =INDEX(Service_Input!$D:$D, MATCH($C$4&"|"&F$7&"|"&$A14, Service_Input!$E:$E, 0)) | G14: =INDEX(Service_Input!$D:$D, MATCH($C$4&"|"&G$7&"|"&$A14, Service_Input!$E:$E, 0)) | H14: =INDEX(Service_Input!$D:$D, MATCH($C$4&"|"&H$7&"|"&$A14, Service_Input!$E:$E, 0)) | I14: =INDEX(Service_Input!$D:$D, MATCH($C$4&"|"&I$7&"|"&$A14, Service_Input!$E:$E, 0)) | ... L14: =INDEX(Service_Input!$D:$D, MATCH($C$4&"|"&L$7&"|"&$A14, Service_Input!$E:$E, 0))

Sheet Product_Dashboard
B2: PRODUCT AVAILABILITY MATRIX (Auto-Calculated)
B4: Select Region: | C4: USA | E4: *Calculated based on dependencies (e.g. SSA requires ASR, GenAI, KaaS)
A7: Language | B7: SSA | C7: RTGA | D7: CIA | E7: CRA
A8: English | B8: =IF(OR(ISNUMBER(SEARCH("Not Supported", INDEX(Service_Input!$D:$D, MATCH($C$4&"|ASR|"&$A8, Service_Input!$E:$E, 0)))), ISNUMBER(SEARCH("Not Supported", INDEX(Service_Input!$D:$D, MATCH($C$4&"|SSA-LLM|"&$A8, Service_Input!$E:$E, 0)))), ISNUMBER(SEARCH("Not Supported", INDEX(Service_Input!$D:$D, MATCH($C$4&"|KaaS|"&$A8, Service_Input!$E:$E, 0))))), "Not Supported", IF(OR(ISNUMBER(SEARCH("Limited Support", INDEX(Service_Input!$D:$D, MATCH($C$4&"|ASR|"&$A8, Service_Input!$E:$E, 0)))), ISNUMBER(SEARCH("Limited Support", INDEX(Service_Input!$D:$D, MATCH($C$4&"|SSA-LLM|"&$A8, Service_Input!$E:$E, 0)))), ISNUMBER(SEARCH("Limited Support", INDEX(Service_Input!$D:$D, MATCH($C$4&"|KaaS|"&$A8, Service_Input!$E:$E, 0))))), IF(OR(ISNUMBER(SEARCH("Cross-Region", INDEX(Service_Input!$D:$D, MATCH($C$4&"|ASR|"&$A8, Service_Input!$E:$E, 0)))), ISNUMBER(SEARCH("Cross-Region", INDEX(Service_Input!$D:$D, MATCH($C$4&"|SSA-LLM|"&$A8, Service_Input!$E:$E, 0)))), ISNUMBER(SEARCH("Cross-Region", INDEX(Service_Input!$D:$D, MATCH($C$4&"|KaaS|"&$A8, Service_Input!$E:$E, 0))))), "Limited Support (Cross-Region)", "Limited Support (In-Region)"), IF(OR(ISNUMBER(SEARCH("Cross-Region", INDEX(Service_Input!$D:$D, MATCH($C$4&"|ASR|"&$A8, Service_Input!$E:$E, 0)))), ISNUMBER(SEARCH("Cross-Region", INDEX(Service_Input!$D:$D, MATCH($C$4&"|SSA-LLM|"&$A8, Service_Input!$E:$E, 0)))), ISNUMBER(SEARCH("Cross-Region", INDEX(Service_Input!$D:$D, MATCH($C$4&"|KaaS|"&$A8, Service_Input!$E:$E, 0))))), "Full Support (Cross-Region)", "Full Support (In-Region)"))) | C8: =IF(OR(ISNUMBER(SEARCH("Not Supported", INDEX(Service_Input!$D:$D, MATCH($C$4&"|ASR|"&$A8, Service_Input!$E:$E, 0)))), ISNUMBER(SEARCH("Not Supported", INDEX(Service_Input!$D:$D, MATCH($C$4&"|Intent (UniFit)|"&$A8, Service_Input!$E:$E, 0)))), ISNUMBER(SEARCH("Not Supported", INDEX(Service_Input!$D:$D, MATCH($C$4&"|Entity (NER/Spacy)|"&$A8, Service_Input!$E:$E, 0)))), ISNUMBER(SEARCH("Not Supported", INDEX(Service_Input!$D:$D, MATCH($C$4&"|Gen AI Summary|"&$A8, Service_Input!$E:$E, 0)))), ISNUMBER(SEARCH("Not Supported", INDEX(Service_Input!$D:$D, MATCH($C$4&"|Gen AI Disposition|"&$A8, Service_Input!$E:$E, 0)))), ISNUMBER(SEARCH("Not Supported", INDEX(Service_Input!$D:$D, MATCH($C$4&"|Redaction|"&$A8, Service_Input!$E:$E, 0)))), ISNUMBER(SEARCH("Not Supported", INDEX(Service_Input!$D:$D, MATCH($C$4&"|KaaS|"&$A8, Service_Input!$E:$E, 0)))), ISNUMBER(SEARCH("Not Supported", INDEX(Service_Input!$D:$D, MATCH($C$4&"|Pro-active Service|"&$A8, Service_Input!$E:$E, 0))))), "Not Supported", IF(OR(ISNUMBER(SEARCH("Limited Support", INDEX(Service_Input!$D:$D, MATCH($C$4&"|ASR|"&$A8, Service_Input!$E:$E, 0)))), ISNUMBER(SEARCH("Limited Support", INDEX(Service_Input!$D:$D, MATCH($C$4&"|Intent (UniFit)|"&$A8, Service_Input!$E:$E, 0)))), ISNUMBER(SEARCH("Limited Support", INDEX(Service_Input!$D:$D, MATCH($C$4&"|Entity (NER/Spacy)|"&$A8, Service_Input!$E:$E, 0)))), ISNUMBER(SEARCH("Limited Support", INDEX(Service_Input!$D:$D, MATCH($C$4&"|Gen AI Summary|"&$A8, Service_Input!$E:$E, 0)))), ISNUMBER(SEARCH("Limited Support", INDEX(Service_Input!$D:$D, MATCH($C$4&"|Gen AI Disposition|"&$A8, Service_Input!$E:$E, 0)))), ISNUMBER(SEARCH("Limited Support", INDEX(Service_Input!$D:$D, MATCH($C$4&"|Redaction|"&$A8, Service_Input!$E:$E, 0)))), ISNUMBER(SEARCH("Limited Support", INDEX(Service_Input!$D:$D, MATCH($C$4&"|KaaS|"&$A8, Service_Input!$E:$E, 0)))), ISNUMBER(SEARCH("Limited Support", INDEX(Service_Input!$D:$D, MATCH($C$4&"|Pro-active Service|"&$A8, Service_Input!$E:$E, 0))))), IF(OR(ISNUMBER(SEARCH("Cross-Region", INDEX(Service_Input!$D:$D, MATCH($C$4&"|ASR|"&$A8, Service_Input!$E:$E, 0)))), ISNUMBER(SEARCH("Cross-Region", INDEX(Service_Input!$D:$D, MATCH($C$4&"|Intent (UniFit)|"&$A8, Service_Input!$E:$E, 0)))), ISNUMBER(SEARCH("Cross-Region", INDEX(Service_Input!$D:$D, MATCH($C$4&"|Entity (NER/Spacy)|"&$A8, Service_Input!$E:$E, 0)))), ISNUMBER(SEARCH("Cross-Region", INDEX(Service_Input!$D:$D, MATCH($C$4&"|Gen AI Summary|"&$A8, Service_Input!$E:$E, 0)))), ISNUMBER(SEARCH("Cross-Region", INDEX(Service_Input!$D:$D, MATCH($C$4&"|Gen AI Disposition|"&$A8, Service_Input!$E:$E, 0)))), ISNUMBER(SEARCH("Cross-Region", INDEX(Service_Input!$D:$D, MATCH($C$4&"|Redaction|"&$A8, Service_Input!$E:$E, 0)))), ISNUMBER(SEARCH("Cross-Region", INDEX(Service_Input!$D:$D, MATCH($C$4&"|KaaS|"&$A8, Service_Input!$E:$E, 0)))), ISNUMBER(SEARCH("Cross-Region", INDEX(Service_Input!$D:$D, MATCH($C$4&"|Pro-active Service|"&$A8, Service_Input!$E:$E, 0))))), "Limited Support (Cross-Region)", "Limited Support (In-Region)"), IF(OR(ISNUMBER(SEARCH("Cross-Region", INDEX(Service_Input!$D:$D, MATCH($C$4&"|ASR|"&$A8, Service_Input!$E:$E, 0)))), ISNUMBER(SEARCH("Cross-Region", INDEX(Service_Input!$D:$D, MATCH($C$4&"|Intent (UniFit)|"&$A8, Service_Input!$E:$E, 0)))), ISNUMBER(SEARCH("Cross-Region", INDEX(Service_Input!$D:$D, MATCH($C$4&"|Entity (NER/Spacy)|"&$A8, Service_Input!$E:$E, 0)))), ISNUMBER(SEARCH("Cross-Region", INDEX(Service_Input!$D:$D, MATCH($C$4&"|Gen AI Summary|"&$A8, Service_Input!$E:$E, 0)))), ISNUMBER(SEARCH("Cross-Region", INDEX(Service_Input!$D:$D, MATCH($C$4&"|Gen AI Disposition|"&$A8, Service_Input!$E:$E, 0)))), ISNUMBER(SEARCH("Cross-Region", INDEX(Service_Input!$D:$D, MATCH($C$4&"|Redaction|"&$A8, Service_Input!$E:$E, 0)))), ISNUMBER(SEARCH("Cross-Region", INDEX(Service_Input!$D:$D, MATCH($C$4&"|KaaS|"&$A8, Service_Input!$E:$E, 0)))), ISNUMBER(SEARCH("Cross-Region", INDEX(Service_Input!$D:$D, MATCH($C$4&"|Pro-active Service|"&$A8, Service_Input!$E:$E, 0))))), "Full Support (Cross-Region)", "Full Support (In-Region)"))) | D8: =IF(OR(ISNUMBER(SEARCH("Not Supported", INDEX(Service_Input!$D:$D, MATCH($C$4&"|ASR|"&$A8, Service_Input!$E:$E, 0)))), ISNUMBER(SEARCH("Not Supported", INDEX(Service_Input!$D:$D, MATCH($C$4&"|Gen AI Disposition|"&$A8, Service_Input!$E:$E, 0)))), ISNUMBER(SEARCH("Not Supported", INDEX(Service_Input!$D:$D, MATCH($C$4&"|Redaction|"&$A8, Service_Input!$E:$E, 0)))), ISNUMBER(SEARCH("Not Supported", INDEX(Service_Input!$D:$D, MATCH($C$4&"|Conversation Facts|"&$A8, Service_Input!$E:$E, 0))))), "Not Supported", IF(OR(ISNUMBER(SEARCH("Limited Support", INDEX(Service_Input!$D:$D, MATCH($C$4&"|ASR|"&$A8, Service_Input!$E:$E, 0)))), ISNUMBER(SEARCH("Limited Support", INDEX(Service_Input!$D:$D, MATCH($C$4&"|Gen AI Disposition|"&$A8, Service_Input!$E:$E, 0)))), ISNUMBER(SEARCH("Limited Support", INDEX(Service_Input!$D:$D, MATCH($C$4&"|Redaction|"&$A8, Service_Input!$E:$E, 0)))), ISNUMBER(SEARCH("Limited Support", INDEX(Service_Input!$D:$D, MATCH($C$4&"|Conversation Facts|"&$A8, Service_Input!$E:$E, 0))))), IF(OR(ISNUMBER(SEARCH("Cross-Region", INDEX(Service_Input!$D:$D, MATCH($C$4&"|ASR|"&$A8, Service_Input!$E:$E, 0)))), ISNUMBER(SEARCH("Cross-Region", INDEX(Service_Input!$D:$D, MATCH($C$4&"|Gen AI Disposition|"&$A8, Service_Input!$E:$E, 0)))), ISNUMBER(SEARCH("Cross-Region", INDEX(Service_Input!$D:$D, MATCH($C$4&"|Redaction|"&$A8, Service_Input!$E:$E, 0)))), ISNUMBER(SEARCH("Cross-Region", INDEX(Service_Input!$D:$D, MATCH($C$4&"|Conversation Facts|"&$A8, Service_Input!$E:$E, 0))))), "Limited Support (Cross-Region)", "Limited Support (In-Region)"), IF(OR(ISNUMBER(SEARCH("Cross-Region", INDEX(Service_Input!$D:$D, MATCH($C$4&"|ASR|"&$A8, Service_Input!$E:$E, 0)))), ISNUMBER(SEARCH("Cross-Region", INDEX(Service_Input!$D:$D, MATCH($C$4&"|Gen AI Disposition|"&$A8, Service_Input!$E:$E, 0)))), ISNUMBER(SEARCH("Cross-Region", INDEX(Service_Input!$D:$D, MATCH($C$4&"|Redaction|"&$A8, Service_Input!$E:$E, 0)))), ISNUMBER(SEARCH("Cross-Region", INDEX(Service_Input!$D:$D, MATCH($C$4&"|Conversation Facts|"&$A8, Service_Input!$E:$E, 0))))), "Full Support (Cross-Region)", "Full Support (In-Region)"))) | E8: =IF(OR(ISNUMBER(SEARCH("Not Supported", INDEX(Service_Input!$D:$D, MATCH($C$4&"|ASR|"&$A8, Service_Input!$E:$E, 0)))), ISNUMBER(SEARCH("Not Supported", INDEX(Service_Input!$D:$D, MATCH($C$4&"|Redaction|"&$A8, Service_Input!$E:$E, 0))))), "Not Supported", IF(OR(ISNUMBER(SEARCH("Limited Support", INDEX(Service_Input!$D:$D, MATCH($C$4&"|ASR|"&$A8, Service_Input!$E:$E, 0)))), ISNUMBER(SEARCH("Limited Support", INDEX(Service_Input!$D:$D, MATCH($C$4&"|Redaction|"&$A8, Service_Input!$E:$E, 0))))), IF(OR(ISNUMBER(SEARCH("Cross-Region", INDEX(Service_Input!$D:$D, MATCH($C$4&"|ASR|"&$A8, Service_Input!$E:$E, 0)))), ISNUMBER(SEARCH("Cross-Region", INDEX(Service_Input!$D:$D, MATCH($C$4&"|Redaction|"&$A8, Service_Input!$E:$E, 0))))), "Limited Support (Cross-Region)", "Limited Support (In-Region)"), IF(OR(ISNUMBER(SEARCH("Cross-Region", INDEX(Service_Input!$D:$D, MATCH($C$4&"|ASR|"&$A8, Service_Input!$E:$E, 0)))), ISNUMBER(SEARCH("Cross-Region", INDEX(Service_Input!$D:$D, MATCH($C$4&"|Redaction|"&$A8, Service_Input!$E:$E, 0))))), "Full Support (Cross-Region)", "Full Support (In-Region)")))
A9: Hindi | B9: =IF(OR(ISNUMBER(SEARCH("Not Supported", INDEX(Service_Input!$D:$D, MATCH($C$4&"|ASR|"&$A9, Service_Input!$E:$E, 0)))), ISNUMBER(SEARCH("Not Supported", INDEX(Service_Input!$D:$D, MATCH($C$4&"|SSA-LLM|"&$A9, Service_Input!$E:$E, 0)))), ISNUMBER(SEARCH("Not Supported", INDEX(Service_Input!$D:$D, MATCH($C$4&"|KaaS|"&$A9, Service_Input!$E:$E, 0))))), "Not Supported", IF(OR(ISNUMBER(SEARCH("Limited Support", INDEX(Service_Input!$D:$D, MATCH($C$4&"|ASR|"&$A9, Service_Input!$E:$E, 0)))), ISNUMBER(SEARCH("Limited Support", INDEX(Service_Input!$D:$D, MATCH($C$4&"|SSA-LLM|"&$A9, Service_Input!$E:$E, 0)))), ISNUMBER(SEARCH("Limited Support", INDEX(Service_Input!$D:$D, MATCH($C$4&"|KaaS|"&$A9, Service_Input!$E:$E, 0))))), IF(OR(ISNUMBER(SEARCH("Cross-Region", INDEX(Service_Input!$D:$D, MATCH($C$4&"|ASR|"&$A9, Service_Input!$E:$E, 0)))), ISNUMBER(SEARCH("Cross-Region", INDEX(Service_Input!$D:$D, MATCH($C$4&"|SSA-LLM|"&$A9, Service_Input!$E:$E, 0)))), ISNUMBER(SEARCH("Cross-Region", INDEX(Service_Input!$D:$D, MATCH($C$4&"|KaaS|"&$A9, Service_Input!$E:$E, 0))))), "Limited Support (Cross-Region)", "Limited Support (In-Region)"), IF(OR(ISNUMBER(SEARCH("Cross-Region", INDEX(Service_Input!$D:$D, MATCH($C$4&"|ASR|"&$A9, Service_Input!$E:$E, 0)))), ISNUMBER(SEARCH("Cross-Region", INDEX(Service_Input!$D:$D, MATCH($C$4&"|SSA-LLM|"&$A9, Service_Input!$E:$E, 0)))), ISNUMBER(SEARCH("Cross-Region", INDEX(Service_Input!$D:$D, MATCH($C$4&"|KaaS|"&$A9, Service_Input!$E:$E, 0))))), "Full Support (Cross-Region)", "Full Support (In-Region)"))) | C9: =IF(OR(ISNUMBER(SEARCH("Not Supported", INDEX(Service_Input!$D:$D, MATCH($C$4&"|ASR|"&$A9, Service_Input!$E:$E, 0)))), ISNUMBER(SEARCH("Not Supported", INDEX(Service_Input!$D:$D, MATCH($C$4&"|Intent (UniFit)|"&$A9, Service_Input!$E:$E, 0)))), ISNUMBER(SEARCH("Not Supported", INDEX(Service_Input!$D:$D, MATCH($C$4&"|Entity (NER/Spacy)|"&$A9, Service_Input!$E:$E, 0)))), ISNUMBER(SEARCH("Not Supported", INDEX(Service_Input!$D:$D, MATCH($C$4&"|Gen AI Summary|"&$A9, Service_Input!$E:$E, 0)))), ISNUMBER(SEARCH("Not Supported", INDEX(Service_Input!$D:$D, MATCH($C$4&"|Gen AI Disposition|"&$A9, Service_Input!$E:$E, 0)))), ISNUMBER(SEARCH("Not Supported", INDEX(Service_Input!$D:$D, MATCH($C$4&"|Redaction|"&$A9, Service_Input!$E:$E, 0)))), ISNUMBER(SEARCH("Not Supported", INDEX(Service_Input!$D:$D, MATCH($C$4&"|KaaS|"&$A9, Service_Input!$E:$E, 0)))), ISNUMBER(SEARCH("Not Supported", INDEX(Service_Input!$D:$D, MATCH($C$4&"|Pro-active Service|"&$A9, Service_Input!$E:$E, 0))))), "Not Supported", IF(OR(ISNUMBER(SEARCH("Limited Support", INDEX(Service_Input!$D:$D, MATCH($C$4&"|ASR|"&$A9, Service_Input!$E:$E, 0)))), ISNUMBER(SEARCH("Limited Support", INDEX(Service_Input!$D:$D, MATCH($C$4&"|Intent (UniFit)|"&$A9, Service_Input!$E:$E, 0)))), ISNUMBER(SEARCH("Limited Support", INDEX(Service_Input!$D:$D, MATCH($C$4&"|Entity (NER/Spacy)|"&$A9, Service_Input!$E:$E, 0)))), ISNUMBER(SEARCH("Limited Support", INDEX(Service_Input!$D:$D, MATCH($C$4&"|Gen AI Summary|"&$A9, Service_Input!$E:$E, 0)))), ISNUMBER(SEARCH("Limited Support", INDEX(Service_Input!$D:$D, MATCH($C$4&"|Gen AI Disposition|"&$A9, Service_Input!$E:$E, 0)))), ISNUMBER(SEARCH("Limited Support", INDEX(Service_Input!$D:$D, MATCH($C$4&"|Redaction|"&$A9, Service_Input!$E:$E, 0)))), ISNUMBER(SEARCH("Limited Support", INDEX(Service_Input!$D:$D, MATCH($C$4&"|KaaS|"&$A9, Service_Input!$E:$E, 0)))), ISNUMBER(SEARCH("Limited Support", INDEX(Service_Input!$D:$D, MATCH($C$4&"|Pro-active Service|"&$A9, Service_Input!$E:$E, 0))))), IF(OR(ISNUMBER(SEARCH("Cross-Region", INDEX(Service_Input!$D:$D, MATCH($C$4&"|ASR|"&$A9, Service_Input!$E:$E, 0)))), ISNUMBER(SEARCH("Cross-Region", INDEX(Service_Input!$D:$D, MATCH($C$4&"|Intent (UniFit)|"&$A9, Service_Input!$E:$E, 0)))), ISNUMBER(SEARCH("Cross-Region", INDEX(Service_Input!$D:$D, MATCH($C$4&"|Entity (NER/Spacy)|"&$A9, Service_Input!$E:$E, 0)))), ISNUMBER(SEARCH("Cross-Region", INDEX(Service_Input!$D:$D, MATCH($C$4&"|Gen AI Summary|"&$A9, Service_Input!$E:$E, 0)))), ISNUMBER(SEARCH("Cross-Region", INDEX(Service_Input!$D:$D, MATCH($C$4&"|Gen AI Disposition|"&$A9, Service_Input!$E:$E, 0)))), ISNUMBER(SEARCH("Cross-Region", INDEX(Service_Input!$D:$D, MATCH($C$4&"|Redaction|"&$A9, Service_Input!$E:$E, 0)))), ISNUMBER(SEARCH("Cross-Region", INDEX(Service_Input!$D:$D, MATCH($C$4&"|KaaS|"&$A9, Service_Input!$E:$E, 0)))), ISNUMBER(SEARCH("Cross-Region", INDEX(Service_Input!$D:$D, MATCH($C$4&"|Pro-active Service|"&$A9, Service_Input!$E:$E, 0))))), "Limited Support (Cross-Region)", "Limited Support (In-Region)"), IF(OR(ISNUMBER(SEARCH("Cross-Region", INDEX(Service_Input!$D:$D, MATCH($C$4&"|ASR|"&$A9, Service_Input!$E:$E, 0)))), ISNUMBER(SEARCH("Cross-Region", INDEX(Service_Input!$D:$D, MATCH($C$4&"|Intent (UniFit)|"&$A9, Service_Input!$E:$E, 0)))), ISNUMBER(SEARCH("Cross-Region", INDEX(Service_Input!$D:$D, MATCH($C$4&"|Entity (NER/Spacy)|"&$A9, Service_Input!$E:$E, 0)))), ISNUMBER(SEARCH("Cross-Region", INDEX(Service_Input!$D:$D, MATCH($C$4&"|Gen AI Summary|"&$A9, Service_Input!$E:$E, 0)))), ISNUMBER(SEARCH("Cross-Region", INDEX(Service_Input!$D:$D, MATCH($C$4&"|Gen AI Disposition|"&$A9, Service_Input!$E:$E, 0)))), ISNUMBER(SEARCH("Cross-Region", INDEX(Service_Input!$D:$D, MATCH($C$4&"|Redaction|"&$A9, Service_Input!$E:$E, 0)))), ISNUMBER(SEARCH("Cross-Region", INDEX(Service_Input!$D:$D, MATCH($C$4&"|KaaS|"&$A9, Service_Input!$E:$E, 0)))), ISNUMBER(SEARCH("Cross-Region", INDEX(Service_Input!$D:$D, MATCH($C$4&"|Pro-active Service|"&$A9, Service_Input!$E:$E, 0))))), "Full Support (Cross-Region)", "Full Support (In-Region)"))) | D9: =IF(OR(ISNUMBER(SEARCH("Not Supported", INDEX(Service_Input!$D:$D, MATCH($C$4&"|ASR|"&$A9, Service_Input!$E:$E, 0)))), ISNUMBER(SEARCH("Not Supported", INDEX(Service_Input!$D:$D, MATCH($C$4&"|Gen AI Disposition|"&$A9, Service_Input!$E:$E, 0)))), ISNUMBER(SEARCH("Not Supported", INDEX(Service_Input!$D:$D, MATCH($C$4&"|Redaction|"&$A9, Service_Input!$E:$E, 0)))), ISNUMBER(SEARCH("Not Supported", INDEX(Service_Input!$D:$D, MATCH($C$4&"|Conversation Facts|"&$A9, Service_Input!$E:$E, 0))))), "Not Supported", IF(OR(ISNUMBER(SEARCH("Limited Support", INDEX(Service_Input!$D:$D, MATCH($C$4&"|ASR|"&$A9, Service_Input!$E:$E, 0)))), ISNUMBER(SEARCH("Limited Support", INDEX(Service_Input!$D:$D, MATCH($C$4&"|Gen AI Disposition|"&$A9, Service_Input!$E:$E, 0)))), ISNUMBER(SEARCH("Limited Support", INDEX(Service_Input!$D:$D, MATCH($C$4&"|Redaction|"&$A9, Service_Input!$E:$E, 0)))), ISNUMBER(SEARCH("Limited Support", INDEX(Service_Input!$D:$D, MATCH($C$4&"|Conversation Facts|"&$A9, Service_Input!$E:$E, 0))))), IF(OR(ISNUMBER(SEARCH("Cross-Region", INDEX(Service_Input!$D:$D, MATCH($C$4&"|ASR|"&$A9, Service_Input!$E:$E, 0)))), ISNUMBER(SEARCH("Cross-Region", INDEX(Service_Input!$D:$D, MATCH($C$4&"|Gen AI Disposition|"&$A9, Service_Input!$E:$E, 0)))), ISNUMBER(SEARCH("Cross-Region", INDEX(Service_Input!$D:$D, MATCH($C$4&"|Redaction|"&$A9, Service_Input!$E:$E, 0)))), ISNUMBER(SEARCH("Cross-Region", INDEX(Service_Input!$D:$D, MATCH($C$4&"|Conversation Facts|"&$A9, Service_Input!$E:$E, 0))))), "Limited Support (Cross-Region)", "Limited Support (In-Region)"), IF(OR(ISNUMBER(SEARCH("Cross-Region", INDEX(Service_Input!$D:$D, MATCH($C$4&"|ASR|"&$A9, Service_Input!$E:$E, 0)))), ISNUMBER(SEARCH("Cross-Region", INDEX(Service_Input!$D:$D, MATCH($C$4&"|Gen AI Disposition|"&$A9, Service_Input!$E:$E, 0)))), ISNUMBER(SEARCH("Cross-Region", INDEX(Service_Input!$D:$D, MATCH($C$4&"|Redaction|"&$A9, Service_Input!$E:$E, 0)))), ISNUMBER(SEARCH("Cross-Region", INDEX(Service_Input!$D:$D, MATCH($C$4&"|Conversation Facts|"&$A9, Service_Input!$E:$E, 0))))), "Full Support (Cross-Region)", "Full Support (In-Region)"))) | E9: =IF(OR(ISNUMBER(SEARCH("Not Supported", INDEX(Service_Input!$D:$D, MATCH($C$4&"|ASR|"&$A9, Service_Input!$E:$E, 0)))), ISNUMBER(SEARCH("Not Supported", INDEX(Service_Input!$D:$D, MATCH($C$4&"|Redaction|"&$A9, Service_Input!$E:$E, 0))))), "Not Supported", IF(OR(ISNUMBER(SEARCH("Limited Support", INDEX(Service_Input!$D:$D, MATCH($C$4&"|ASR|"&$A9, Service_Input!$E:$E, 0)))), ISNUMBER(SEARCH("Limited Support", INDEX(Service_Input!$D:$D, MATCH($C$4&"|Redaction|"&$A9, Service_Input!$E:$E, 0))))), IF(OR(ISNUMBER(SEARCH("Cross-Region", INDEX(Service_Input!$D:$D, MATCH($C$4&"|ASR|"&$A9, Service_Input!$E:$E, 0)))), ISNUMBER(SEARCH("Cross-Region", INDEX(Service_Input!$D:$D, MATCH($C$4&"|Redaction|"&$A9, Service_Input!$E:$E, 0))))), "Limited Support (Cross-Region)", "Limited Support (In-Region)"), IF(OR(ISNUMBER(SEARCH("Cross-Region", INDEX(Service_Input!$D:$D, MATCH($C$4&"|ASR|"&$A9, Service_Input!$E:$E, 0)))), ISNUMBER(SEARCH("Cross-Region", INDEX(Service_Input!$D:$D, MATCH($C$4&"|Redaction|"&$A9, Service_Input!$E:$E, 0))))), "Full Support (Cross-Region)", "Full Support (In-Region)")))
A10: Spanish | B10: =IF(OR(ISNUMBER(SEARCH("Not Supported", INDEX(Service_Input!$D:$D, MATCH($C$4&"|ASR|"&$A10, Service_Input!$E:$E, 0)))), ISNUMBER(SEARCH("Not Supported", INDEX(Service_Input!$D:$D, MATCH($C$4&"|SSA-LLM|"&$A10, Service_Input!$E:$E, 0)))), ISNUMBER(SEARCH("Not Supported", INDEX(Service_Input!$D:$D, MATCH($C$4&"|KaaS|"&$A10, Service_Input!$E:$E, 0))))), "Not Supported", IF(OR(ISNUMBER(SEARCH("Limited Support", INDEX(Service_Input!$D:$D, MATCH($C$4&"|ASR|"&$A10, Service_Input!$E:$E, 0)))), ISNUMBER(SEARCH("Limited Support", INDEX(Service_Input!$D:$D, MATCH($C$4&"|SSA-LLM|"&$A10, Service_Input!$E:$E, 0)))), ISNUMBER(SEARCH("Limited Support", INDEX(Service_Input!$D:$D, MATCH($C$4&"|KaaS|"&$A10, Service_Input!$E:$E, 0))))), IF(OR(ISNUMBER(SEARCH("Cross-Region", INDEX(Service_Input!$D:$D, MATCH($C$4&"|ASR|"&$A10, Service_Input!$E:$E, 0)))), ISNUMBER(SEARCH("Cross-Region", INDEX(Service_Input!$D:$D, MATCH($C$4&"|SSA-LLM|"&$A10, Service_Input!$E:$E, 0)))), ISNUMBER(SEARCH("Cross-Region", INDEX(Service_Input!$D:$D, MATCH($C$4&"|KaaS|"&$A10, Service_Input!$E:$E, 0))))), "Limited Support (Cross-Region)", "Limited Support (In-Region)"), IF(OR(ISNUMBER(SEARCH("Cross-Region", INDEX(Service_Input!$D:$D, MATCH($C$4&"|ASR|"&$A10, Service_Input!$E:$E, 0)))), ISNUMBER(SEARCH("Cross-Region", INDEX(Service_Input!$D:$D, MATCH($C$4&"|SSA-LLM|"&$A10, Service_Input!$E:$E, 0)))), ISNUMBER(SEARCH("Cross-Region", INDEX(Service_Input!$D:$D, MATCH($C$4&"|KaaS|"&$A10, Service_Input!$E:$E, 0))))), "Full Support (Cross-Region)", "Full Support (In-Region)"))) | C10: =IF(OR(ISNUMBER(SEARCH("Not Supported", INDEX(Service_Input!$D:$D, MATCH($C$4&"|ASR|"&$A10, Service_Input!$E:$E, 0)))), ISNUMBER(SEARCH("Not Supported", INDEX(Service_Input!$D:$D, MATCH($C$4&"|Intent (UniFit)|"&$A10, Service_Input!$E:$E, 0)))), ISNUMBER(SEARCH("Not Supported", INDEX(Service_Input!$D:$D, MATCH($C$4&"|Entity (NER/Spacy)|"&$A10, Service_Input!$E:$E, 0)))), ISNUMBER(SEARCH("Not Supported", INDEX(Service_Input!$D:$D, MATCH($C$4&"|Gen AI Summary|"&$A10, Service_Input!$E:$E, 0)))), ISNUMBER(SEARCH("Not Supported", INDEX(Service_Input!$D:$D, MATCH($C$4&"|Gen AI Disposition|"&$A10, Service_Input!$E:$E, 0)))), ISNUMBER(SEARCH("Not Supported", INDEX(Service_Input!$D:$D, MATCH($C$4&"|Redaction|"&$A10, Service_Input!$E:$E, 0)))), ISNUMBER(SEARCH("Not Supported", INDEX(Service_Input!$D:$D, MATCH($C$4&"|KaaS|"&$A10, Service_Input!$E:$E, 0)))), ISNUMBER(SEARCH("Not Supported", INDEX(Service_Input!$D:$D, MATCH($C$4&"|Pro-active Service|"&$A10, Service_Input!$E:$E, 0))))), "Not Supported", IF(OR(ISNUMBER(SEARCH("Limited Support", INDEX(Service_Input!$D:$D, MATCH($C$4&"|ASR|"&$A10, Service_Input!$E:$E, 0)))), ISNUMBER(SEARCH("Limited Support", INDEX(Service_Input!$D:$D, MATCH($C$4&"|Intent (UniFit)|"&$A10, Service_Input!$E:$E, 0)))), ISNUMBER(SEARCH("Limited Support", INDEX(Service_Input!$D:$D, MATCH($C$4&"|Entity (NER/Spacy)|"&$A10, Service_Input!$E:$E, 0)))), ISNUMBER(SEARCH("Limited Support", INDEX(Service_Input!$D:$D, MATCH($C$4&"|Gen AI Summary|"&$A10, Service_Input!$E:$E, 0)))), ISNUMBER(SEARCH("Limited Support", INDEX(Service_Input!$D:$D, MATCH($C$4&"|Gen AI Disposition|"&$A10, Service_Input!$E:$E, 0)))), ISNUMBER(SEARCH("Limited Support", INDEX(Service_Input!$D:$D, MATCH($C$4&"|Redaction|"&$A10, Service_Input!$E:$E, 0)))), ISNUMBER(SEARCH("Limited Support", INDEX(Service_Input!$D:$D, MATCH($C$4&"|KaaS|"&$A10, Service_Input!$E:$E, 0)))), ISNUMBER(SEARCH("Limited Support", INDEX(Service_Input!$D:$D, MATCH($C$4&"|Pro-active Service|"&$A10, Service_Input!$E:$E, 0))))), IF(OR(ISNUMBER(SEARCH("Cross-Region", INDEX(Service_Input!$D:$D, MATCH($C$4&"|ASR|"&$A10, Service_Input!$E:$E, 0)))), ISNUMBER(SEARCH("Cross-Region", INDEX(Service_Input!$D:$D, MATCH($C$4&"|Intent (UniFit)|"&$A10, Service_Input!$E:$E, 0)))), ISNUMBER(SEARCH("Cross-Region", INDEX(Service_Input!$D:$D, MATCH($C$4&"|Entity (NER/Spacy)|"&$A10, Service_Input!$E:$E, 0)))), ISNUMBER(SEARCH("Cross-Region", INDEX(Service_Input!$D:$D, MATCH($C$4&"|Gen AI Summary|"&$A10, Service_Input!$E:$E, 0)))), ISNUMBER(SEARCH("Cross-Region", INDEX(Service_Input!$D:$D, MATCH($C$4&"|Gen AI Disposition|"&$A10, Service_Input!$E:$E, 0)))), ISNUMBER(SEARCH("Cross-Region", INDEX(Service_Input!$D:$D, MATCH($C$4&"|Redaction|"&$A10, Service_Input!$E:$E, 0)))), ISNUMBER(SEARCH("Cross-Region", INDEX(Service_Input!$D:$D, MATCH($C$4&"|KaaS|"&$A10, Service_Input!$E:$E, 0)))), ISNUMBER(SEARCH("Cross-Region", INDEX(Service_Input!$D:$D, MATCH($C$4&"|Pro-active Service|"&$A10, Service_Input!$E:$E, 0))))), "Limited Support (Cross-Region)", "Limited Support (In-Region)"), IF(OR(ISNUMBER(SEARCH("Cross-Region", INDEX(Service_Input!$D:$D, MATCH($C$4&"|ASR|"&$A10, Service_Input!$E:$E, 0)))), ISNUMBER(SEARCH("Cross-Region", INDEX(Service_Input!$D:$D, MATCH($C$4&"|Intent (UniFit)|"&$A10, Service_Input!$E:$E, 0)))), ISNUMBER(SEARCH("Cross-Region", INDEX(Service_Input!$D:$D, MATCH($C$4&"|Entity (NER/Spacy)|"&$A10, Service_Input!$E:$E, 0)))), ISNUMBER(SEARCH("Cross-Region", INDEX(Service_Input!$D:$D, MATCH($C$4&"|Gen AI Summary|"&$A10, Service_Input!$E:$E, 0)))), ISNUMBER(SEARCH("Cross-Region", INDEX(Service_Input!$D:$D, MATCH($C$4&"|Gen AI Disposition|"&$A10, Service_Input!$E:$E, 0)))), ISNUMBER(SEARCH("Cross-Region", INDEX(Service_Input!$D:$D, MATCH($C$4&"|Redaction|"&$A10, Service_Input!$E:$E, 0)))), ISNUMBER(SEARCH("Cross-Region", INDEX(Service_Input!$D:$D, MATCH($C$4&"|KaaS|"&$A10, Service_Input!$E:$E, 0)))), ISNUMBER(SEARCH("Cross-Region", INDEX(Service_Input!$D:$D, MATCH($C$4&"|Pro-active Service|"&$A10, Service_Input!$E:$E, 0))))), "Full Support (Cross-Region)", "Full Support (In-Region)"))) | D10: =IF(OR(ISNUMBER(SEARCH("Not Supported", INDEX(Service_Input!$D:$D, MATCH($C$4&"|ASR|"&$A10, Service_Input!$E:$E, 0)))), ISNUMBER(SEARCH("Not Supported", INDEX(Service_Input!$D:$D, MATCH($C$4&"|Gen AI Disposition|"&$A10, Service_Input!$E:$E, 0)))), ISNUMBER(SEARCH("Not Supported", INDEX(Service_Input!$D:$D, MATCH($C$4&"|Redaction|"&$A10, Service_Input!$E:$E, 0)))), ISNUMBER(SEARCH("Not Supported", INDEX(Service_Input!$D:$D, MATCH($C$4&"|Conversation Facts|"&$A10, Service_Input!$E:$E, 0))))), "Not Supported", IF(OR(ISNUMBER(SEARCH("Limited Support", INDEX(Service_Input!$D:$D, MATCH($C$4&"|ASR|"&$A10, Service_Input!$E:$E, 0)))), ISNUMBER(SEARCH("Limited Support", INDEX(Service_Input!$D:$D, MATCH($C$4&"|Gen AI Disposition|"&$A10, Service_Input!$E:$E, 0)))), ISNUMBER(SEARCH("Limited Support", INDEX(Service_Input!$D:$D, MATCH($C$4&"|Redaction|"&$A10, Service_Input!$E:$E, 0)))), ISNUMBER(SEARCH("Limited Support", INDEX(Service_Input!$D:$D, MATCH($C$4&"|Conversation Facts|"&$A10, Service_Input!$E:$E, 0))))), IF(OR(ISNUMBER(SEARCH("Cross-Region", INDEX(Service_Input!$D:$D, MATCH($C$4&"|ASR|"&$A10, Service_Input!$E:$E, 0)))), ISNUMBER(SEARCH("Cross-Region", INDEX(Service_Input!$D:$D, MATCH($C$4&"|Gen AI Disposition|"&$A10, Service_Input!$E:$E, 0)))), ISNUMBER(SEARCH("Cross-Region", INDEX(Service_Input!$D:$D, MATCH($C$4&"|Redaction|"&$A10, Service_Input!$E:$E, 0)))), ISNUMBER(SEARCH("Cross-Region", INDEX(Service_Input!$D:$D, MATCH($C$4&"|Conversation Facts|"&$A10, Service_Input!$E:$E, 0))))), "Limited Support (Cross-Region)", "Limited Support (In-Region)"), IF(OR(ISNUMBER(SEARCH("Cross-Region", INDEX(Service_Input!$D:$D, MATCH($C$4&"|ASR|"&$A10, Service_Input!$E:$E, 0)))), ISNUMBER(SEARCH("Cross-Region", INDEX(Service_Input!$D:$D, MATCH($C$4&"|Gen AI Disposition|"&$A10, Service_Input!$E:$E, 0)))), ISNUMBER(SEARCH("Cross-Region", INDEX(Service_Input!$D:$D, MATCH($C$4&"|Redaction|"&$A10, Service_Input!$E:$E, 0)))), ISNUMBER(SEARCH("Cross-Region", INDEX(Service_Input!$D:$D, MATCH($C$4&"|Conversation Facts|"&$A10, Service_Input!$E:$E, 0))))), "Full Support (Cross-Region)", "Full Support (In-Region)"))) | E10: =IF(OR(ISNUMBER(SEARCH("Not Supported", INDEX(Service_Input!$D:$D, MATCH($C$4&"|ASR|"&$A10, Service_Input!$E:$E, 0)))), ISNUMBER(SEARCH("Not Supported", INDEX(Service_Input!$D:$D, MATCH($C$4&"|Redaction|"&$A10, Service_Input!$E:$E, 0))))), "Not Supported", IF(OR(ISNUMBER(SEARCH("Limited Support", INDEX(Service_Input!$D:$D, MATCH($C$4&"|ASR|"&$A10, Service_Input!$E:$E, 0)))), ISNUMBER(SEARCH("Limited Support", INDEX(Service_Input!$D:$D, MATCH($C$4&"|Redaction|"&$A10, Service_Input!$E:$E, 0))))), IF(OR(ISNUMBER(SEARCH("Cross-Region", INDEX(Service_Input!$D:$D, MATCH($C$4&"|ASR|"&$A10, Service_Input!$E:$E, 0)))), ISNUMBER(SEARCH("Cross-Region", INDEX(Service_Input!$D:$D, MATCH($C$4&"|Redaction|"&$A10, Service_Input!$E:$E, 0))))), "Limited Support (Cross-Region)", "Limited Support (In-Region)"), IF(OR(ISNUMBER(SEARCH("Cross-Region", INDEX(Service_Input!$D:$D, MATCH($C$4&"|ASR|"&$A10, Service_Input!$E:$E, 0)))), ISNUMBER(SEARCH("Cross-Region", INDEX(Service_Input!$D:$D, MATCH($C$4&"|Redaction|"&$A10, Service_Input!$E:$E, 0))))), "Full Support (Cross-Region)", "Full Support (In-Region)")))
A11: German | B11: =IF(OR(ISNUMBER(SEARCH("Not Supported", INDEX(Service_Input!$D:$D, MATCH($C$4&"|ASR|"&$A11, Service_Input!$E:$E, 0)))), ISNUMBER(SEARCH("Not Supported", INDEX(Service_Input!$D:$D, MATCH($C$4&"|SSA-LLM|"&$A11, Service_Input!$E:$E, 0)))), ISNUMBER(SEARCH("Not Supported", INDEX(Service_Input!$D:$D, MATCH($C$4&"|KaaS|"&$A11, Service_Input!$E:$E, 0))))), "Not Supported", IF(OR(ISNUMBER(SEARCH("Limited Support", INDEX(Service_Input!$D:$D, MATCH($C$4&"|ASR|"&$A11, Service_Input!$E:$E, 0)))), ISNUMBER(SEARCH("Limited Support", INDEX(Service_Input!$D:$D, MATCH($C$4&"|SSA-LLM|"&$A11, Service_Input!$E:$E, 0)))), ISNUMBER(SEARCH("Limited Support", INDEX(Service_Input!$D:$D, MATCH($C$4&"|KaaS|"&$A11, Service_Input!$E:$E, 0))))), IF(OR(ISNUMBER(SEARCH("Cross-Region", INDEX(Service_Input!$D:$D, MATCH($C$4&"|ASR|"&$A11, Service_Input!$E:$E, 0)))), ISNUMBER(SEARCH("Cross-Region", INDEX(Service_Input!$D:$D, MATCH($C$4&"|SSA-LLM|"&$A11, Service_Input!$E:$E, 0)))), ISNUMBER(SEARCH("Cross-Region", INDEX(Service_Input!$D:$D, MATCH($C$4&"|KaaS|"&$A11, Service_Input!$E:$E, 0))))), "Limited Support (Cross-Region)", "Limited Support (In-Region)"), IF(OR(ISNUMBER(SEARCH("Cross-Region", INDEX(Service_Input!$D:$D, MATCH($C$4&"|ASR|"&$A11, Service_Input!$E:$E, 0)))), ISNUMBER(SEARCH("Cross-Region", INDEX(Service_Input!$D:$D, MATCH($C$4&"|SSA-LLM|"&$A11, Service_Input!$E:$E, 0)))), ISNUMBER(SEARCH("Cross-Region", INDEX(Service_Input!$D:$D, MATCH($C$4&"|KaaS|"&$A11, Service_Input!$E:$E, 0))))), "Full Support (Cross-Region)", "Full Support (In-Region)"))) | C11: =IF(OR(ISNUMBER(SEARCH("Not Supported", INDEX(Service_Input!$D:$D, MATCH($C$4&"|ASR|"&$A11, Service_Input!$E:$E, 0)))), ISNUMBER(SEARCH("Not Supported", INDEX(Service_Input!$D:$D, MATCH($C$4&"|Intent (UniFit)|"&$A11, Service_Input!$E:$E, 0)))), ISNUMBER(SEARCH("Not Supported", INDEX(Service_Input!$D:$D, MATCH($C$4&"|Entity (NER/Spacy)|"&$A11, Service_Input!$E:$E, 0)))), ISNUMBER(SEARCH("Not Supported", INDEX(Service_Input!$D:$D, MATCH($C$4&"|Gen AI Summary|"&$A11, Service_Input!$E:$E, 0)))), ISNUMBER(SEARCH("Not Supported", INDEX(Service_Input!$D:$D, MATCH($C$4&"|Gen AI Disposition|"&$A11, Service_Input!$E:$E, 0)))), ISNUMBER(SEARCH("Not Supported", INDEX(Service_Input!$D:$D, MATCH($C$4&"|Redaction|"&$A11, Service_Input!$E:$E, 0)))), ISNUMBER(SEARCH("Not Supported", INDEX(Service_Input!$D:$D, MATCH($C$4&"|KaaS|"&$A11, Service_Input!$E:$E, 0)))), ISNUMBER(SEARCH("Not Supported", INDEX(Service_Input!$D:$D, MATCH($C$4&"|Pro-active Service|"&$A11, Service_Input!$E:$E, 0))))), "Not Supported", IF(OR(ISNUMBER(SEARCH("Limited Support", INDEX(Service_Input!$D:$D, MATCH($C$4&"|ASR|"&$A11, Service_Input!$E:$E, 0)))), ISNUMBER(SEARCH("Limited Support", INDEX(Service_Input!$D:$D, MATCH($C$4&"|Intent (UniFit)|"&$A11, Service_Input!$E:$E, 0)))), ISNUMBER(SEARCH("Limited Support", INDEX(Service_Input!$D:$D, MATCH($C$4&"|Entity (NER/Spacy)|"&$A11, Service_Input!$E:$E, 0)))), ISNUMBER(SEARCH("Limited Support", INDEX(Service_Input!$D:$D, MATCH($C$4&"|Gen AI Summary|"&$A11, Service_Input!$E:$E, 0)))), ISNUMBER(SEARCH("Limited Support", INDEX(Service_Input!$D:$D, MATCH($C$4&"|Gen AI Disposition|"&$A11, Service_Input!$E:$E, 0)))), ISNUMBER(SEARCH("Limited Support", INDEX(Service_Input!$D:$D, MATCH($C$4&"|Redaction|"&$A11, Service_Input!$E:$E, 0)))), ISNUMBER(SEARCH("Limited Support", INDEX(Service_Input!$D:$D, MATCH($C$4&"|KaaS|"&$A11, Service_Input!$E:$E, 0)))), ISNUMBER(SEARCH("Limited Support", INDEX(Service_Input!$D:$D, MATCH($C$4&"|Pro-active Service|"&$A11, Service_Input!$E:$E, 0))))), IF(OR(ISNUMBER(SEARCH("Cross-Region", INDEX(Service_Input!$D:$D, MATCH($C$4&"|ASR|"&$A11, Service_Input!$E:$E, 0)))), ISNUMBER(SEARCH("Cross-Region", INDEX(Service_Input!$D:$D, MATCH($C$4&"|Intent (UniFit)|"&$A11, Service_Input!$E:$E, 0)))), ISNUMBER(SEARCH("Cross-Region", INDEX(Service_Input!$D:$D, MATCH($C$4&"|Entity (NER/Spacy)|"&$A11, Service_Input!$E:$E, 0)))), ISNUMBER(SEARCH("Cross-Region", INDEX(Service_Input!$D:$D, MATCH($C$4&"|Gen AI Summary|"&$A11, Service_Input!$E:$E, 0)))), ISNUMBER(SEARCH("Cross-Region", INDEX(Service_Input!$D:$D, MATCH($C$4&"|Gen AI Disposition|"&$A11, Service_Input!$E:$E, 0)))), ISNUMBER(SEARCH("Cross-Region", INDEX(Service_Input!$D:$D, MATCH($C$4&"|Redaction|"&$A11, Service_Input!$E:$E, 0)))), ISNUMBER(SEARCH("Cross-Region", INDEX(Service_Input!$D:$D, MATCH($C$4&"|KaaS|"&$A11, Service_Input!$E:$E, 0)))), ISNUMBER(SEARCH("Cross-Region", INDEX(Service_Input!$D:$D, MATCH($C$4&"|Pro-active Service|"&$A11, Service_Input!$E:$E, 0))))), "Limited Support (Cross-Region)", "Limited Support (In-Region)"), IF(OR(ISNUMBER(SEARCH("Cross-Region", INDEX(Service_Input!$D:$D, MATCH($C$4&"|ASR|"&$A11, Service_Input!$E:$E, 0)))), ISNUMBER(SEARCH("Cross-Region", INDEX(Service_Input!$D:$D, MATCH($C$4&"|Intent (UniFit)|"&$A11, Service_Input!$E:$E, 0)))), ISNUMBER(SEARCH("Cross-Region", INDEX(Service_Input!$D:$D, MATCH($C$4&"|Entity (NER/Spacy)|"&$A11, Service_Input!$E:$E, 0)))), ISNUMBER(SEARCH("Cross-Region", INDEX(Service_Input!$D:$D, MATCH($C$4&"|Gen AI Summary|"&$A11, Service_Input!$E:$E, 0)))), ISNUMBER(SEARCH("Cross-Region", INDEX(Service_Input!$D:$D, MATCH($C$4&"|Gen AI Disposition|"&$A11, Service_Input!$E:$E, 0)))), ISNUMBER(SEARCH("Cross-Region", INDEX(Service_Input!$D:$D, MATCH($C$4&"|Redaction|"&$A11, Service_Input!$E:$E, 0)))), ISNUMBER(SEARCH("Cross-Region", INDEX(Service_Input!$D:$D, MATCH($C$4&"|KaaS|"&$A11, Service_Input!$E:$E, 0)))), ISNUMBER(SEARCH("Cross-Region", INDEX(Service_Input!$D:$D, MATCH($C$4&"|Pro-active Service|"&$A11, Service_Input!$E:$E, 0))))), "Full Support (Cross-Region)", "Full Support (In-Region)"))) | D11: =IF(OR(ISNUMBER(SEARCH("Not Supported", INDEX(Service_Input!$D:$D, MATCH($C$4&"|ASR|"&$A11, Service_Input!$E:$E, 0)))), ISNUMBER(SEARCH("Not Supported", INDEX(Service_Input!$D:$D, MATCH($C$4&"|Gen AI Disposition|"&$A11, Service_Input!$E:$E, 0)))), ISNUMBER(SEARCH("Not Supported", INDEX(Service_Input!$D:$D, MATCH($C$4&"|Redaction|"&$A11, Service_Input!$E:$E, 0)))), ISNUMBER(SEARCH("Not Supported", INDEX(Service_Input!$D:$D, MATCH($C$4&"|Conversation Facts|"&$A11, Service_Input!$E:$E, 0))))), "Not Supported", IF(OR(ISNUMBER(SEARCH("Limited Support", INDEX(Service_Input!$D:$D, MATCH($C$4&"|ASR|"&$A11, Service_Input!$E:$E, 0)))), ISNUMBER(SEARCH("Limited Support", INDEX(Service_Input!$D:$D, MATCH($C$4&"|Gen AI Disposition|"&$A11, Service_Input!$E:$E, 0)))), ISNUMBER(SEARCH("Limited Support", INDEX(Service_Input!$D:$D, MATCH($C$4&"|Redaction|"&$A11, Service_Input!$E:$E, 0)))), ISNUMBER(SEARCH("Limited Support", INDEX(Service_Input!$D:$D, MATCH($C$4&"|Conversation Facts|"&$A11, Service_Input!$E:$E, 0))))), IF(OR(ISNUMBER(SEARCH("Cross-Region", INDEX(Service_Input!$D:$D, MATCH($C$4&"|ASR|"&$A11, Service_Input!$E:$E, 0)))), ISNUMBER(SEARCH("Cross-Region", INDEX(Service_Input!$D:$D, MATCH($C$4&"|Gen AI Disposition|"&$A11, Service_Input!$E:$E, 0)))), ISNUMBER(SEARCH("Cross-Region", INDEX(Service_Input!$D:$D, MATCH($C$4&"|Redaction|"&$A11, Service_Input!$E:$E, 0)))), ISNUMBER(SEARCH("Cross-Region", INDEX(Service_Input!$D:$D, MATCH($C$4&"|Conversation Facts|"&$A11, Service_Input!$E:$E, 0))))), "Limited Support (Cross-Region)", "Limited Support (In-Region)"), IF(OR(ISNUMBER(SEARCH("Cross-Region", INDEX(Service_Input!$D:$D, MATCH($C$4&"|ASR|"&$A11, Service_Input!$E:$E, 0)))), ISNUMBER(SEARCH("Cross-Region", INDEX(Service_Input!$D:$D, MATCH($C$4&"|Gen AI Disposition|"&$A11, Service_Input!$E:$E, 0)))), ISNUMBER(SEARCH("Cross-Region", INDEX(Service_Input!$D:$D, MATCH($C$4&"|Redaction|"&$A11, Service_Input!$E:$E, 0)))), ISNUMBER(SEARCH("Cross-Region", INDEX(Service_Input!$D:$D, MATCH($C$4&"|Conversation Facts|"&$A11, Service_Input!$E:$E, 0))))), "Full Support (Cross-Region)", "Full Support (In-Region)"))) | E11: =IF(OR(ISNUMBER(SEARCH("Not Supported", INDEX(Service_Input!$D:$D, MATCH($C$4&"|ASR|"&$A11, Service_Input!$E:$E, 0)))), ISNUMBER(SEARCH("Not Supported", INDEX(Service_Input!$D:$D, MATCH($C$4&"|Redaction|"&$A11, Service_Input!$E:$E, 0))))), "Not Supported", IF(OR(ISNUMBER(SEARCH("Limited Support", INDEX(Service_Input!$D:$D, MATCH($C$4&"|ASR|"&$A11, Service_Input!$E:$E, 0)))), ISNUMBER(SEARCH("Limited Support", INDEX(Service_Input!$D:$D, MATCH($C$4&"|Redaction|"&$A11, Service_Input!$E:$E, 0))))), IF(OR(ISNUMBER(SEARCH("Cross-Region", INDEX(Service_Input!$D:$D, MATCH($C$4&"|ASR|"&$A11, Service_Input!$E:$E, 0)))), ISNUMBER(SEARCH("Cross-Region", INDEX(Service_Input!$D:$D, MATCH($C$4&"|Redaction|"&$A11, Service_Input!$E:$E, 0))))), "Limited Support (Cross-Region)", "Limited Support (In-Region)"), IF(OR(ISNUMBER(SEARCH("Cross-Region", INDEX(Service_Input!$D:$D, MATCH($C$4&"|ASR|"&$A11, Service_Input!$E:$E, 0)))), ISNUMBER(SEARCH("Cross-Region", INDEX(Service_Input!$D:$D, MATCH($C$4&"|Redaction|"&$A11, Service_Input!$E:$E, 0))))), "Full Support (Cross-Region)", "Full Support (In-Region)")))
A12: Arabic | B12: =IF(OR(ISNUMBER(SEARCH("Not Supported", INDEX(Service_Input!$D:$D, MATCH($C$4&"|ASR|"&$A12, Service_Input!$E:$E, 0)))), ISNUMBER(SEARCH("Not Supported", INDEX(Service_Input!$D:$D, MATCH($C$4&"|SSA-LLM|"&$A12, Service_Input!$E:$E, 0)))), ISNUMBER(SEARCH("Not Supported", INDEX(Service_Input!$D:$D, MATCH($C$4&"|KaaS|"&$A12, Service_Input!$E:$E, 0))))), "Not Supported", IF(OR(ISNUMBER(SEARCH("Limited Support", INDEX(Service_Input!$D:$D, MATCH($C$4&"|ASR|"&$A12, Service_Input!$E:$E, 0)))), ISNUMBER(SEARCH("Limited Support", INDEX(Service_Input!$D:$D, MATCH($C$4&"|SSA-LLM|"&$A12, Service_Input!$E:$E, 0)))), ISNUMBER(SEARCH("Limited Support", INDEX(Service_Input!$D:$D, MATCH($C$4&"|KaaS|"&$A12, Service_Input!$E:$E, 0))))), IF(OR(ISNUMBER(SEARCH("Cross-Region", INDEX(Service_Input!$D:$D, MATCH($C$4&"|ASR|"&$A12, Service_Input!$E:$E, 0)))), ISNUMBER(SEARCH("Cross-Region", INDEX(Service_Input!$D:$D, MATCH($C$4&"|SSA-LLM|"&$A12, Service_Input!$E:$E, 0)))), ISNUMBER(SEARCH("Cross-Region", INDEX(Service_Input!$D:$D, MATCH($C$4&"|KaaS|"&$A12, Service_Input!$E:$E, 0))))), "Limited Support (Cross-Region)", "Limited Support (In-Region)"), IF(OR(ISNUMBER(SEARCH("Cross-Region", INDEX(Service_Input!$D:$D, MATCH($C$4&"|ASR|"&$A12, Service_Input!$E:$E, 0)))), ISNUMBER(SEARCH("Cross-Region", INDEX(Service_Input!$D:$D, MATCH($C$4&"|SSA-LLM|"&$A12, Service_Input!$E:$E, 0)))), ISNUMBER(SEARCH("Cross-Region", INDEX(Service_Input!$D:$D, MATCH($C$4&"|KaaS|"&$A12, Service_Input!$E:$E, 0))))), "Full Support (Cross-Region)", "Full Support (In-Region)"))) | C12: =IF(OR(ISNUMBER(SEARCH("Not Supported", INDEX(Service_Input!$D:$D, MATCH($C$4&"|ASR|"&$A12, Service_Input!$E:$E, 0)))), ISNUMBER(SEARCH("Not Supported", INDEX(Service_Input!$D:$D, MATCH($C$4&"|Intent (UniFit)|"&$A12, Service_Input!$E:$E, 0)))), ISNUMBER(SEARCH("Not Supported", INDEX(Service_Input!$D:$D, MATCH($C$4&"|Entity (NER/Spacy)|"&$A12, Service_Input!$E:$E, 0)))), ISNUMBER(SEARCH("Not Supported", INDEX(Service_Input!$D:$D, MATCH($C$4&"|Gen AI Summary|"&$A12, Service_Input!$E:$E, 0)))), ISNUMBER(SEARCH("Not Supported", INDEX(Service_Input!$D:$D, MATCH($C$4&"|Gen AI Disposition|"&$A12, Service_Input!$E:$E, 0)))), ISNUMBER(SEARCH("Not Supported", INDEX(Service_Input!$D:$D, MATCH($C$4&"|Redaction|"&$A12, Service_Input!$E:$E, 0)))), ISNUMBER(SEARCH("Not Supported", INDEX(Service_Input!$D:$D, MATCH($C$4&"|KaaS|"&$A12, Service_Input!$E:$E, 0)))), ISNUMBER(SEARCH("Not Supported", INDEX(Service_Input!$D:$D, MATCH($C$4&"|Pro-active Service|"&$A12, Service_Input!$E:$E, 0))))), "Not Supported", IF(OR(ISNUMBER(SEARCH("Limited Support", INDEX(Service_Input!$D:$D, MATCH($C$4&"|ASR|"&$A12, Service_Input!$E:$E, 0)))), ISNUMBER(SEARCH("Limited Support", INDEX(Service_Input!$D:$D, MATCH($C$4&"|Intent (UniFit)|"&$A12, Service_Input!$E:$E, 0)))), ISNUMBER(SEARCH("Limited Support", INDEX(Service_Input!$D:$D, MATCH($C$4&"|Entity (NER/Spacy)|"&$A12, Service_Input!$E:$E, 0)))), ISNUMBER(SEARCH("Limited Support", INDEX(Service_Input!$D:$D, MATCH($C$4&"|Gen AI Summary|"&$A12, Service_Input!$E:$E, 0)))), ISNUMBER(SEARCH("Limited Support", INDEX(Service_Input!$D:$D, MATCH($C$4&"|Gen AI Disposition|"&$A12, Service_Input!$E:$E, 0)))), ISNUMBER(SEARCH("Limited Support", INDEX(Service_Input!$D:$D, MATCH($C$4&"|Redaction|"&$A12, Service_Input!$E:$E, 0)))), ISNUMBER(SEARCH("Limited Support", INDEX(Service_Input!$D:$D, MATCH($C$4&"|KaaS|"&$A12, Service_Input!$E:$E, 0)))), ISNUMBER(SEARCH("Limited Support", INDEX(Service_Input!$D:$D, MATCH($C$4&"|Pro-active Service|"&$A12, Service_Input!$E:$E, 0))))), IF(OR(ISNUMBER(SEARCH("Cross-Region", INDEX(Service_Input!$D:$D, MATCH($C$4&"|ASR|"&$A12, Service_Input!$E:$E, 0)))), ISNUMBER(SEARCH("Cross-Region", INDEX(Service_Input!$D:$D, MATCH($C$4&"|Intent (UniFit)|"&$A12, Service_Input!$E:$E, 0)))), ISNUMBER(SEARCH("Cross-Region", INDEX(Service_Input!$D:$D, MATCH($C$4&"|Entity (NER/Spacy)|"&$A12, Service_Input!$E:$E, 0)))), ISNUMBER(SEARCH("Cross-Region", INDEX(Service_Input!$D:$D, MATCH($C$4&"|Gen AI Summary|"&$A12, Service_Input!$E:$E, 0)))), ISNUMBER(SEARCH("Cross-Region", INDEX(Service_Input!$D:$D, MATCH($C$4&"|Gen AI Disposition|"&$A12, Service_Input!$E:$E, 0)))), ISNUMBER(SEARCH("Cross-Region", INDEX(Service_Input!$D:$D, MATCH($C$4&"|Redaction|"&$A12, Service_Input!$E:$E, 0)))), ISNUMBER(SEARCH("Cross-Region", INDEX(Service_Input!$D:$D, MATCH($C$4&"|KaaS|"&$A12, Service_Input!$E:$E, 0)))), ISNUMBER(SEARCH("Cross-Region", INDEX(Service_Input!$D:$D, MATCH($C$4&"|Pro-active Service|"&$A12, Service_Input!$E:$E, 0))))), "Limited Support (Cross-Region)", "Limited Support (In-Region)"), IF(OR(ISNUMBER(SEARCH("Cross-Region", INDEX(Service_Input!$D:$D, MATCH($C$4&"|ASR|"&$A12, Service_Input!$E:$E, 0)))), ISNUMBER(SEARCH("Cross-Region", INDEX(Service_Input!$D:$D, MATCH($C$4&"|Intent (UniFit)|"&$A12, Service_Input!$E:$E, 0)))), ISNUMBER(SEARCH("Cross-Region", INDEX(Service_Input!$D:$D, MATCH($C$4&"|Entity (NER/Spacy)|"&$A12, Service_Input!$E:$E, 0)))), ISNUMBER(SEARCH("Cross-Region", INDEX(Service_Input!$D:$D, MATCH($C$4&"|Gen AI Summary|"&$A12, Service_Input!$E:$E, 0)))), ISNUMBER(SEARCH("Cross-Region", INDEX(Service_Input!$D:$D, MATCH($C$4&"|Gen AI Disposition|"&$A12, Service_Input!$E:$E, 0)))), ISNUMBER(SEARCH("Cross-Region", INDEX(Service_Input!$D:$D, MATCH($C$4&"|Redaction|"&$A12, Service_Input!$E:$E, 0)))), ISNUMBER(SEARCH("Cross-Region", INDEX(Service_Input!$D:$D, MATCH($C$4&"|KaaS|"&$A12, Service_Input!$E:$E, 0)))), ISNUMBER(SEARCH("Cross-Region", INDEX(Service_Input!$D:$D, MATCH($C$4&"|Pro-active Service|"&$A12, Service_Input!$E:$E, 0))))), "Full Support (Cross-Region)", "Full Support (In-Region)"))) | D12: =IF(OR(ISNUMBER(SEARCH("Not Supported", INDEX(Service_Input!$D:$D, MATCH($C$4&"|ASR|"&$A12, Service_Input!$E:$E, 0)))), ISNUMBER(SEARCH("Not Supported", INDEX(Service_Input!$D:$D, MATCH($C$4&"|Gen AI Disposition|"&$A12, Service_Input!$E:$E, 0)))), ISNUMBER(SEARCH("Not Supported", INDEX(Service_Input!$D:$D, MATCH($C$4&"|Redaction|"&$A12, Service_Input!$E:$E, 0)))), ISNUMBER(SEARCH("Not Supported", INDEX(Service_Input!$D:$D, MATCH($C$4&"|Conversation Facts|"&$A12, Service_Input!$E:$E, 0))))), "Not Supported", IF(OR(ISNUMBER(SEARCH("Limited Support", INDEX(Service_Input!$D:$D, MATCH($C$4&"|ASR|"&$A12, Service_Input!$E:$E, 0)))), ISNUMBER(SEARCH("Limited Support", INDEX(Service_Input!$D:$D, MATCH($C$4&"|Gen AI Disposition|"&$A12, Service_Input!$E:$E, 0)))), ISNUMBER(SEARCH("Limited Support", INDEX(Service_Input!$D:$D, MATCH($C$4&"|Redaction|"&$A12, Service_Input!$E:$E, 0)))), ISNUMBER(SEARCH("Limited Support", INDEX(Service_Input!$D:$D, MATCH($C$4&"|Conversation Facts|"&$A12, Service_Input!$E:$E, 0))))), IF(OR(ISNUMBER(SEARCH("Cross-Region", INDEX(Service_Input!$D:$D, MATCH($C$4&"|ASR|"&$A12, Service_Input!$E:$E, 0)))), ISNUMBER(SEARCH("Cross-Region", INDEX(Service_Input!$D:$D, MATCH($C$4&"|Gen AI Disposition|"&$A12, Service_Input!$E:$E, 0)))), ISNUMBER(SEARCH("Cross-Region", INDEX(Service_Input!$D:$D, MATCH($C$4&"|Redaction|"&$A12, Service_Input!$E:$E, 0)))), ISNUMBER(SEARCH("Cross-Region", INDEX(Service_Input!$D:$D, MATCH($C$4&"|Conversation Facts|"&$A12, Service_Input!$E:$E, 0))))), "Limited Support (Cross-Region)", "Limited Support (In-Region)"), IF(OR(ISNUMBER(SEARCH("Cross-Region", INDEX(Service_Input!$D:$D, MATCH($C$4&"|ASR|"&$A12, Service_Input!$E:$E, 0)))), ISNUMBER(SEARCH("Cross-Region", INDEX(Service_Input!$D:$D, MATCH($C$4&"|Gen AI Disposition|"&$A12, Service_Input!$E:$E, 0)))), ISNUMBER(SEARCH("Cross-Region", INDEX(Service_Input!$D:$D, MATCH($C$4&"|Redaction|"&$A12, Service_Input!$E:$E, 0)))), ISNUMBER(SEARCH("Cross-Region", INDEX(Service_Input!$D:$D, MATCH($C$4&"|Conversation Facts|"&$A12, Service_Input!$E:$E, 0))))), "Full Support (Cross-Region)", "Full Support (In-Region)"))) | E12: =IF(OR(ISNUMBER(SEARCH("Not Supported", INDEX(Service_Input!$D:$D, MATCH($C$4&"|ASR|"&$A12, Service_Input!$E:$E, 0)))), ISNUMBER(SEARCH("Not Supported", INDEX(Service_Input!$D:$D, MATCH($C$4&"|Redaction|"&$A12, Service_Input!$E:$E, 0))))), "Not Supported", IF(OR(ISNUMBER(SEARCH("Limited Support", INDEX(Service_Input!$D:$D, MATCH($C$4&"|ASR|"&$A12, Service_Input!$E:$E, 0)))), ISNUMBER(SEARCH("Limited Support", INDEX(Service_Input!$D:$D, MATCH($C$4&"|Redaction|"&$A12, Service_Input!$E:$E, 0))))), IF(OR(ISNUMBER(SEARCH("Cross-Region", INDEX(Service_Input!$D:$D, MATCH($C$4&"|ASR|"&$A12, Service_Input!$E:$E, 0)))), ISNUMBER(SEARCH("Cross-Region", INDEX(Service_Input!$D:$D, MATCH($C$4&"|Redaction|"&$A12, Service_Input!$E:$E, 0))))), "Limited Support (Cross-Region)", "Limited Support (In-Region)"), IF(OR(ISNUMBER(SEARCH("Cross-Region", INDEX(Service_Input!$D:$D, MATCH($C$4&"|ASR|"&$A12, Service_Input!$E:$E, 0)))), ISNUMBER(SEARCH("Cross-Region", INDEX(Service_Input!$D:$D, MATCH($C$4&"|Redaction|"&$A12, Service_Input!$E:$E, 0))))), "Full Support (Cross-Region)", "Full Support (In-Region)")))
